<?xml version="1.0" ?>
<!-- =================================================================================== -->
<!-- |    This document was autogenerated by xacro from /home/ab20/fri_ros_ws/src/HSI/med7PF_description/urdf/lbr_photonfocus_camera.urdf.xacro | -->
<!-- |    EDITING THIS FILE BY HAND IS NOT RECOMMENDED                                 | -->
<!-- =================================================================================== -->
<!-- Here we define the robot, we named it "photonfocus_camera" -->
<robot name="photonfocus_camera">
  <material name="silver">
    <color rgba="0.700 0.700 0.700 1.000"/>
  </material>
  <gazebo>
    <plugin filename="libgazebo_ros_control.so" name="control"/>
  </gazebo>
  <gazebo reference="base_link">
    <material>Gazebo/Silver</material>
    <mu1>0.2</mu1>
    <mu2>0.2</mu2>
    <selfCollide>true</selfCollide>
    <gravity>true</gravity>
  </gazebo>
  <gazebo reference="Component8_1_1_1_1">
    <material>Gazebo/Silver</material>
    <mu1>0.2</mu1>
    <mu2>0.2</mu2>
    <selfCollide>true</selfCollide>
  </gazebo>
  <gazebo reference="Component7_1_1_1_1">
    <material>Gazebo/Silver</material>
    <mu1>0.2</mu1>
    <mu2>0.2</mu2>
    <selfCollide>true</selfCollide>
  </gazebo>
  <gazebo reference="Component6_1_1_1_1">
    <material>Gazebo/Silver</material>
    <mu1>0.2</mu1>
    <mu2>0.2</mu2>
    <selfCollide>true</selfCollide>
  </gazebo>
  <gazebo reference="Component2_1_1_1_1">
    <material>Gazebo/Silver</material>
    <mu1>0.2</mu1>
    <mu2>0.2</mu2>
    <selfCollide>true</selfCollide>
  </gazebo>
  <gazebo reference="Component3_1_1_1_1">
    <material>Gazebo/Silver</material>
    <mu1>0.2</mu1>
    <mu2>0.2</mu2>
    <selfCollide>true</selfCollide>
  </gazebo>
  <gazebo reference="Component4_1_1_1_1">
    <material>Gazebo/Silver</material>
    <mu1>0.2</mu1>
    <mu2>0.2</mu2>
    <selfCollide>true</selfCollide>
  </gazebo>
  <gazebo reference="Component5_1_1_1_1">
    <material>Gazebo/Silver</material>
    <mu1>0.2</mu1>
    <mu2>0.2</mu2>
    <selfCollide>true</selfCollide>
  </gazebo>
  <!-- fix to world -->
  <link name="world"/>
  <!--joint between {parent} and link_0-->
  <joint name="world_lbr_joint" type="fixed">
    <origin rpy="0 0 0" xyz="0 0 0"/>
    <parent link="world"/>
    <child link="lbr_link_0"/>
  </joint>
  <link name="lbr_link_0">
    <inertial>
      <origin rpy="0 0 0" xyz="-0.0018958727522859222 -8.736009549202623e-09 0.07626305487275586"/>
      <mass value="46.20540698229506"/>
      <inertia ixx="0.250291" ixy="-0.0" ixz="-0.004435" iyy="0.255257" iyz="-0.0" izz="0.351803"/>
    </inertial>
    <visual>
      <origin rpy="0 0 0" xyz="0 0 0"/>
      <geometry>
        <mesh filename="package://lbr_description/meshes/med7/visual/link_0.stl"/>
      </geometry>
      <material name="white">
        <color rgba="1.0 1.0 1.0 1.0"/>
      </material>
    </visual>
    <collision>
      <origin rpy="0 0 0" xyz="0 0 0"/>
      <geometry>
        <mesh filename="package://lbr_description/meshes/med7/collision/link_0.stl"/>
      </geometry>
    </collision>
  </link>
  <joint name="lbr_joint_1" type="revolute">
    <origin rpy="0 0 0" xyz="0.0 0.0 0.1475"/>
    <parent link="lbr_link_0"/>
    <child link="lbr_link_1"/>
    <axis xyz="0.0 0.0 0.01"/>
    <limit effort="300" lower="-2.9670597283903604" upper="2.9670597283903604" velocity="10"/>
    <safety_controller k_position="100" k_velocity="2" soft_lower_limit="-2.9321531433504737" soft_upper_limit="2.9321531433504737"/>
    <dynamics damping="0.5"/>
  </joint>
  <link name="lbr_link_1">
    <inertial>
      <origin rpy="0 0 0" xyz="5.010328793588479e-08 -0.03481903813472808 0.12329857163085542"/>
      <mass value="21.161828997118327"/>
      <inertia ixx="0.133324" ixy="-0.0" ixz="0.0" iyy="0.127214" iyz="0.023673" izz="0.047155"/>
    </inertial>
    <visual>
      <origin rpy="0 0 0" xyz="-0.0 0.0 -0.1475"/>
      <geometry>
        <mesh filename="package://lbr_description/meshes/med7/visual/link_1.stl"/>
      </geometry>
      <material name="white">
        <color rgba="1.0 1.0 1.0 1.0"/>
      </material>
    </visual>
    <collision>
      <origin rpy="0 0 0" xyz="-0.0 0.0 -0.1475"/>
      <geometry>
        <mesh filename="package://lbr_description/meshes/med7/collision/link_1.stl"/>
      </geometry>
    </collision>
  </link>
  <joint name="lbr_joint_2" type="revolute">
    <origin rpy="0 0 0" xyz="-0.0 -0.0105 0.1925"/>
    <parent link="lbr_link_1"/>
    <child link="lbr_link_2"/>
    <axis xyz="0.0 0.01 0.0"/>
    <limit effort="300" lower="-2.0943951023931953" upper="2.0943951023931953" velocity="10"/>
    <safety_controller k_position="100" k_velocity="2" soft_lower_limit="-2.0594885173533086" soft_upper_limit="2.0594885173533086"/>
    <dynamics damping="0.5"/>
  </joint>
  <link name="lbr_link_2">
    <inertial>
      <origin rpy="0 0 0" xyz="2.958275959973659e-08 0.03979295468456965 0.08694361150855662"/>
      <mass value="25.13966081800886"/>
      <inertia ixx="0.19763" ixy="-0.0" ixz="0.0" iyy="0.187553" iyz="0.036718" izz="0.060269"/>
    </inertial>
    <visual>
      <origin rpy="0 0 0" xyz="0.0 0.0105 -0.34"/>
      <geometry>
        <mesh filename="package://lbr_description/meshes/med7/visual/link_2.stl"/>
      </geometry>
      <material name="white">
        <color rgba="1.0 1.0 1.0 1.0"/>
      </material>
    </visual>
    <collision>
      <origin rpy="0 0 0" xyz="0.0 0.0105 -0.34"/>
      <geometry>
        <mesh filename="package://lbr_description/meshes/med7/collision/link_2.stl"/>
      </geometry>
    </collision>
  </link>
  <joint name="lbr_joint_3" type="revolute">
    <origin rpy="0 0 0" xyz="0.0 0.0105 0.2075"/>
    <parent link="lbr_link_2"/>
    <child link="lbr_link_3"/>
    <axis xyz="0.0 0.0 0.01"/>
    <limit effort="300" lower="-2.9670597283903604" upper="2.9670597283903604" velocity="10"/>
    <safety_controller k_position="100" k_velocity="2" soft_lower_limit="-2.9321531433504737" soft_upper_limit="2.9321531433504737"/>
    <dynamics damping="0.5"/>
  </joint>
  <link name="lbr_link_3">
    <inertial>
      <origin rpy="0 0 0" xyz="-5.010330962930412e-08 0.03481903813473644 0.1232985716309013"/>
      <mass value="21.1618289971097"/>
      <inertia ixx="0.133324" ixy="-0.0" ixz="-0.0" iyy="0.127214" iyz="-0.023673" izz="0.047155"/>
    </inertial>
    <visual>
      <origin rpy="0 0 0" xyz="0.0 -0.0 -0.5475"/>
      <geometry>
        <mesh filename="package://lbr_description/meshes/med7/visual/link_3.stl"/>
      </geometry>
      <material name="white">
        <color rgba="1.0 1.0 1.0 1.0"/>
      </material>
    </visual>
    <collision>
      <origin rpy="0 0 0" xyz="0.0 -0.0 -0.5475"/>
      <geometry>
        <mesh filename="package://lbr_description/meshes/med7/collision/link_3.stl"/>
      </geometry>
    </collision>
  </link>
  <joint name="lbr_joint_4" type="revolute">
    <origin rpy="0 0 0" xyz="0.0 0.0105 0.1925"/>
    <parent link="lbr_link_3"/>
    <child link="lbr_link_4"/>
    <axis xyz="0.0 -0.01 0.0"/>
    <limit effort="300" lower="-2.0943951023931953" upper="2.0943951023931953" velocity="10"/>
    <safety_controller k_position="100" k_velocity="2" soft_lower_limit="-2.0594885173533086" soft_upper_limit="2.0594885173533086"/>
    <dynamics damping="0.5"/>
  </joint>
  <link name="lbr_link_4">
    <inertial>
      <origin rpy="0 0 0" xyz="-3.025230048709993e-08 -0.03979329512443697 0.08694363375610437"/>
      <mass value="25.139648831600116"/>
      <inertia ixx="0.197618" ixy="-0.0" ixz="-0.0" iyy="0.187546" iyz="-0.036716" izz="0.060263"/>
    </inertial>
    <visual>
      <origin rpy="0 0 0" xyz="-0.0 -0.0105 -0.74"/>
      <geometry>
        <mesh filename="package://lbr_description/meshes/med7/visual/link_4.stl"/>
      </geometry>
      <material name="white">
        <color rgba="1.0 1.0 1.0 1.0"/>
      </material>
    </visual>
    <collision>
      <origin rpy="0 0 0" xyz="-0.0 -0.0105 -0.74"/>
      <geometry>
        <mesh filename="package://lbr_description/meshes/med7/collision/link_4.stl"/>
      </geometry>
    </collision>
  </link>
  <joint name="lbr_joint_5" type="revolute">
    <origin rpy="0 0 0" xyz="-0.0 -0.0105 0.2075"/>
    <parent link="lbr_link_4"/>
    <child link="lbr_link_5"/>
    <axis xyz="0.0 0.0 0.01"/>
    <limit effort="300" lower="-2.9670597283903604" upper="2.9670597283903604" velocity="10"/>
    <safety_controller k_position="100" k_velocity="2" soft_lower_limit="-2.9321531433504737" soft_upper_limit="2.9321531433504737"/>
    <dynamics damping="0.5"/>
  </joint>
  <link name="lbr_link_5">
    <inertial>
      <origin rpy="0 0 0" xyz="3.887174133882675e-08 -0.02982428408876193 0.07626701716135398"/>
      <mass value="9.534880920206515"/>
      <inertia ixx="0.052905" ixy="0.0" ixz="-0.0" iyy="0.044495" iyz="0.017493" izz="0.023991"/>
    </inertial>
    <visual>
      <origin rpy="0 0 0" xyz="0.0 0.0 -0.9475"/>
      <geometry>
        <mesh filename="package://lbr_description/meshes/med7/visual/link_5.stl"/>
      </geometry>
      <material name="white">
        <color rgba="1.0 1.0 1.0 1.0"/>
      </material>
    </visual>
    <collision>
      <origin rpy="0 0 0" xyz="0.0 0.0 -0.9475"/>
      <geometry>
        <mesh filename="package://lbr_description/meshes/med7/collision/link_5.stl"/>
      </geometry>
    </collision>
  </link>
  <joint name="lbr_joint_6" type="revolute">
    <origin rpy="0 0 0" xyz="0.0 -0.0707 0.1925"/>
    <parent link="lbr_link_5"/>
    <child link="lbr_link_6"/>
    <axis xyz="0.0 0.01 0.0"/>
    <limit effort="300" lower="-2.0943951023931953" upper="2.0943951023931953" velocity="10"/>
    <safety_controller k_position="100" k_velocity="2" soft_lower_limit="-2.0594885173533086" soft_upper_limit="2.0594885173533086"/>
    <dynamics damping="0.5"/>
  </joint>
  <link name="lbr_link_6">
    <inertial>
      <origin rpy="0 0 0" xyz="-7.073221144775636e-07 0.07101990943401648 0.004952526180360017"/>
      <mass value="14.987109331100873"/>
      <inertia ixx="0.044068" ixy="-0.0" ixz="1e-06" iyy="0.042427" iyz="0.001941" izz="0.028865"/>
    </inertial>
    <visual>
      <origin rpy="0 0 0" xyz="0.0 0.0707 -1.14"/>
      <geometry>
        <mesh filename="package://lbr_description/meshes/med7/visual/link_6.stl"/>
      </geometry>
      <material name="white">
        <color rgba="1.0 1.0 1.0 1.0"/>
      </material>
    </visual>
    <collision>
      <origin rpy="0 0 0" xyz="0.0 0.0707 -1.14"/>
      <geometry>
        <mesh filename="package://lbr_description/meshes/med7/collision/link_6.stl"/>
      </geometry>
    </collision>
  </link>
  <joint name="lbr_joint_7" type="revolute">
    <origin rpy="0 0 0" xyz="0.0 0.0707 0.091"/>
    <parent link="lbr_link_6"/>
    <child link="lbr_link_7"/>
    <axis xyz="0.0 0.0 0.01"/>
    <limit effort="300" lower="-3.0543261909900763" upper="3.0543261909900763" velocity="10"/>
    <safety_controller k_position="100" k_velocity="2" soft_lower_limit="-3.01941960595019" soft_upper_limit="3.01941960595019"/>
    <dynamics damping="0.5"/>
  </joint>
  <link name="lbr_link_7">
    <inertial>
      <origin rpy="0 0 0" xyz="3.1218274599808524e-06 -1.6358155634513969e-06 0.013782295521067356"/>
      <mass value="1.6178339975962697"/>
      <inertia ixx="0.001066" ixy="0.0" ixz="-0.0" iyy="0.001066" iyz="0.0" izz="0.001864"/>
    </inertial>
    <visual>
      <origin rpy="0 0 0" xyz="-0.0 -0.0 -1.231"/>
      <geometry>
        <mesh filename="package://lbr_description/meshes/med7/visual/link_7.stl"/>
      </geometry>
      <material name="silver">
        <color rgba="0.7 0.7 0.7 1.0"/>
      </material>
    </visual>
    <collision>
      <origin rpy="0 0 0" xyz="-0.0 -0.0 -1.231"/>
      <geometry>
        <mesh filename="package://lbr_description/meshes/med7/collision/link_7.stl"/>
      </geometry>
    </collision>
  </link>
  <joint name="lbr_joint_ee" type="fixed">
    <parent link="lbr_link_7"/>
    <child link="lbr_link_ee"/>
    <origin rpy="0 0 0" xyz="0 0 0.035"/>
  </joint>
  <link name="lbr_link_ee">
        </link>
  <!-- ros_control-plugin -->
  <gazebo>
    <plugin filename="libgazebo_ros_control.so" name="gazebo_ros_control">
      <robotNamespace>/lbr</robotNamespace>
    </plugin>
  </gazebo>
  <!-- link 0 -->
  <gazebo reference="lbr_link_0">
    <mu1>0.2</mu1>
    <mu2>0.2</mu2>
    <material>Gazebo/White</material>
  </gazebo>
  <!-- link 1 -->
  <gazebo reference="lbr_link_1">
    <mu1>0.2</mu1>
    <mu2>0.2</mu2>
    <material>Gazebo/White</material>
  </gazebo>
  <!-- link 2 -->
  <gazebo reference="lbr_link_2">
    <mu1>0.2</mu1>
    <mu2>0.2</mu2>
    <material>Gazebo/White</material>
  </gazebo>
  <!-- link 3 -->
  <gazebo reference="lbr_link_3">
    <mu1>0.2</mu1>
    <mu2>0.2</mu2>
    <material>Gazebo/White</material>
  </gazebo>
  <!-- link 4 -->
  <gazebo reference="lbr_link_4">
    <mu1>0.2</mu1>
    <mu2>0.2</mu2>
    <material>Gazebo/White</material>
  </gazebo>
  <!-- link 5 -->
  <gazebo reference="lbr_link_5">
    <mu1>0.2</mu1>
    <mu2>0.2</mu2>
    <material>Gazebo/White</material>
  </gazebo>
  <!-- link 6 -->
  <gazebo reference="lbr_link_6">
    <mu1>0.2</mu1>
    <mu2>0.2</mu2>
    <material>Gazebo/White</material>
  </gazebo>
  <!-- link 7 -->
  <gazebo reference="lbr_link_7">
    <mu1>0.2</mu1>
    <mu2>0.2</mu2>
    <material>Gazebo/Grey</material>
  </gazebo>
  <!-- joint 1 -->
  <transmission name="lbr_tran_1">
    <robotNamespace>/lbr</robotNamespace>
    <type>transmission_interface/SimpleTransmission</type>
    <joint name="lbr_joint_1">
      <hardwareInterface>hardware_interface/PositionJointInterface</hardwareInterface>
    </joint>
    <actuator name="lbr_motor_1">
      <hardwareInterface>hardware_interface/PositionJointInterface</hardwareInterface>
      <mechanicalReduction>1</mechanicalReduction>
    </actuator>
  </transmission>
  <!-- joint 2 -->
  <transmission name="lbr_tran_2">
    <robotNamespace>/lbr</robotNamespace>
    <type>transmission_interface/SimpleTransmission</type>
    <joint name="lbr_joint_2">
      <hardwareInterface>hardware_interface/PositionJointInterface</hardwareInterface>
    </joint>
    <actuator name="lbr_motor_2">
      <hardwareInterface>hardware_interface/PositionJointInterface</hardwareInterface>
      <mechanicalReduction>1</mechanicalReduction>
    </actuator>
  </transmission>
  <!-- joint 3 -->
  <transmission name="lbr_tran_3">
    <robotNamespace>/lbr</robotNamespace>
    <type>transmission_interface/SimpleTransmission</type>
    <joint name="lbr_joint_3">
      <hardwareInterface>hardware_interface/PositionJointInterface</hardwareInterface>
    </joint>
    <actuator name="lbr_motor_3">
      <hardwareInterface>hardware_interface/PositionJointInterface</hardwareInterface>
      <mechanicalReduction>1</mechanicalReduction>
    </actuator>
  </transmission>
  <!-- joint 4 -->
  <transmission name="lbr_tran_4">
    <robotNamespace>/lbr</robotNamespace>
    <type>transmission_interface/SimpleTransmission</type>
    <joint name="lbr_joint_4">
      <hardwareInterface>hardware_interface/PositionJointInterface</hardwareInterface>
    </joint>
    <actuator name="lbr_motor_4">
      <hardwareInterface>hardware_interface/PositionJointInterface</hardwareInterface>
      <mechanicalReduction>1</mechanicalReduction>
    </actuator>
  </transmission>
  <!-- joint 5 -->
  <transmission name="lbr_tran_5">
    <robotNamespace>/lbr</robotNamespace>
    <type>transmission_interface/SimpleTransmission</type>
    <joint name="lbr_joint_5">
      <hardwareInterface>hardware_interface/PositionJointInterface</hardwareInterface>
    </joint>
    <actuator name="lbr_motor_5">
      <hardwareInterface>hardware_interface/PositionJointInterface</hardwareInterface>
      <mechanicalReduction>1</mechanicalReduction>
    </actuator>
  </transmission>
  <!-- joint 6 -->
  <transmission name="lbr_tran_6">
    <robotNamespace>/lbr</robotNamespace>
    <type>transmission_interface/SimpleTransmission</type>
    <joint name="lbr_joint_6">
      <hardwareInterface>hardware_interface/PositionJointInterface</hardwareInterface>
    </joint>
    <actuator name="lbr_motor_6">
      <hardwareInterface>hardware_interface/PositionJointInterface</hardwareInterface>
      <mechanicalReduction>1</mechanicalReduction>
    </actuator>
  </transmission>
  <!-- joint 7 -->
  <transmission name="lbr_tran_7">
    <robotNamespace>/lbr</robotNamespace>
    <type>transmission_interface/SimpleTransmission</type>
    <joint name="lbr_joint_7">
      <hardwareInterface>hardware_interface/PositionJointInterface</hardwareInterface>
    </joint>
    <actuator name="lbr_motor_7">
      <hardwareInterface>hardware_interface/PositionJointInterface</hardwareInterface>
      <mechanicalReduction>1</mechanicalReduction>
    </actuator>
  </transmission>
  <link name="base_link">
    <inertial>
      <origin rpy="0 0 0" xyz="1.7763568394002505e-17 3.552713678800501e-17 0.0046742040606025685"/>
      <mass value="0.20307198484404515"/>
      <inertia ixx="4.8e-05" ixy="0.0" ixz="0.0" iyy="4.8e-05" iyz="0.0" izz="9.4e-05"/>
    </inertial>
    <visual>
      <origin rpy="0 0 0" xyz="0 0 0"/>
      <geometry>
        <mesh filename="package://photonfocus_camera_description/meshes/base_link.stl" scale="0.001 0.001 0.001"/>
      </geometry>
      <material name="silver"/>
    </visual>
    <collision>
      <origin rpy="0 0 0" xyz="0 0 0"/>
      <geometry>
        <mesh filename="package://photonfocus_camera_description/meshes/base_link.stl" scale="0.001 0.001 0.001"/>
      </geometry>
    </collision>
  </link>
  <link name="Component8_1_1_1_1">
    <inertial>
      <origin rpy="0 0 0" xyz="0.006675819379415325 -0.0009462499931954823 0.025261336246706647"/>
      <mass value="0.1997581385630358"/>
      <inertia ixx="4.8e-05" ixy="-0.0" ixz="-2e-06" iyy="5.1e-05" iyz="-0.0" izz="1.8e-05"/>
    </inertial>
    <visual>
      <origin rpy="0 0 0" xyz="0.005763 -0.000949 -0.009647"/>
      <geometry>
        <mesh filename="package://photonfocus_camera_description/meshes/Component8_1_1_1_1.stl" scale="0.001 0.001 0.001"/>
      </geometry>
      <material name="silver"/>
    </visual>
    <collision>
      <origin rpy="0 0 0" xyz="0.005763 -0.000949 -0.009647"/>
      <geometry>
        <mesh filename="package://photonfocus_camera_description/meshes/Component8_1_1_1_1.stl" scale="0.001 0.001 0.001"/>
      </geometry>
    </collision>
  </link>
  <link name="Component7_1_1_1_1">
    <inertial>
      <origin rpy="0 0 0" xyz="0.00576299999995598 -0.0009489999999999939 0.006999172477632563"/>
      <mass value="0.010061892950917101"/>
      <inertia ixx="0.0" ixy="0.0" ixz="-0.0" iyy="0.0" iyz="0.0" izz="0.0"/>
    </inertial>
    <visual>
      <origin rpy="0 0 0" xyz="0.005763 -0.000949 -0.059647"/>
      <geometry>
        <mesh filename="package://photonfocus_camera_description/meshes/Component7_1_1_1_1.stl" scale="0.001 0.001 0.001"/>
      </geometry>
      <material name="silver"/>
    </visual>
    <collision>
      <origin rpy="0 0 0" xyz="0.005763 -0.000949 -0.059647"/>
      <geometry>
        <mesh filename="package://photonfocus_camera_description/meshes/Component7_1_1_1_1.stl" scale="0.001 0.001 0.001"/>
      </geometry>
    </collision>
  </link>
  <link name="Component6_1_1_1_1">
    <inertial>
      <origin rpy="0 0 0" xyz="0.005761639433104251 -0.009116655198803872 0.0050873760786627475"/>
      <mass value="0.07190809365548972"/>
      <inertia ixx="8e-06" ixy="0.0" ixz="-0.0" iyy="6e-06" iyz="-0.0" izz="1.3e-05"/>
    </inertial>
    <visual>
      <origin rpy="0 0 0" xyz="0.005763 -0.000949 -0.074647"/>
      <geometry>
        <mesh filename="package://photonfocus_camera_description/meshes/Component6_1_1_1_1.stl" scale="0.001 0.001 0.001"/>
      </geometry>
      <material name="silver"/>
    </visual>
    <collision>
      <origin rpy="0 0 0" xyz="0.005763 -0.000949 -0.074647"/>
      <geometry>
        <mesh filename="package://photonfocus_camera_description/meshes/Component6_1_1_1_1.stl" scale="0.001 0.001 0.001"/>
      </geometry>
    </collision>
  </link>
  <link name="Component2_1_1_1_1">
    <inertial>
      <origin rpy="0 0 0" xyz="-0.0012599221198894494 -0.019570473272113073 0.014158631511927311"/>
      <mass value="0.1371138450645388"/>
      <inertia ixx="6.1e-05" ixy="3e-06" ixz="0.0" iyy="2.8e-05" iyz="-3e-06" izz="6.1e-05"/>
    </inertial>
    <visual>
      <origin rpy="0 0 0" xyz="-0.002737 -0.000949 -0.084647"/>
      <geometry>
        <mesh filename="package://photonfocus_camera_description/meshes/Component2_1_1_1_1.stl" scale="0.001 0.001 0.001"/>
      </geometry>
      <material name="silver"/>
    </visual>
    <collision>
      <origin rpy="0 0 0" xyz="-0.002737 -0.000949 -0.084647"/>
      <geometry>
        <mesh filename="package://photonfocus_camera_description/meshes/Component2_1_1_1_1.stl" scale="0.001 0.001 0.001"/>
      </geometry>
    </collision>
  </link>
  <link name="Component3_1_1_1_1">
    <inertial>
      <origin rpy="0 0 0" xyz="-0.017468336612135094 -0.03067971553276897 0.0131744579556861"/>
      <mass value="0.37244365260000467"/>
      <inertia ixx="0.000149" ixy="1e-06" ixz="-5e-05" iyy="0.000171" iyz="1e-06" izz="0.000158"/>
    </inertial>
    <visual>
      <origin rpy="0 0 0" xyz="-0.003122 -0.015981 -0.099947"/>
      <geometry>
        <mesh filename="package://photonfocus_camera_description/meshes/Component3_1_1_1_1.stl" scale="0.001 0.001 0.001"/>
      </geometry>
      <material name="silver"/>
    </visual>
    <collision>
      <origin rpy="0 0 0" xyz="-0.003122 -0.015981 -0.099947"/>
      <geometry>
        <mesh filename="package://photonfocus_camera_description/meshes/Component3_1_1_1_1.stl" scale="0.001 0.001 0.001"/>
      </geometry>
    </collision>
  </link>
  <link name="Component4_1_1_1_1">
    <inertial>
      <origin rpy="0 0 0" xyz="-0.0031593464532001414 -0.07800866004916104 -0.0003471545903905998"/>
      <mass value="0.4535330539476499"/>
      <inertia ixx="0.000157" ixy="-1e-06" ixz="0.0" iyy="9.2e-05" iyz="2e-06" izz="0.000157"/>
    </inertial>
    <visual>
      <origin rpy="0 0 0" xyz="-0.003237 -0.120949 -0.099647"/>
      <geometry>
        <mesh filename="package://photonfocus_camera_description/meshes/Component4_1_1_1_1.stl" scale="0.001 0.001 0.001"/>
      </geometry>
      <material name="silver"/>
    </visual>
    <collision>
      <origin rpy="0 0 0" xyz="-0.003237 -0.120949 -0.099647"/>
      <geometry>
        <mesh filename="package://photonfocus_camera_description/meshes/Component4_1_1_1_1.stl" scale="0.001 0.001 0.001"/>
      </geometry>
    </collision>
  </link>
  <link name="Component5_1_1_1_1">
    <inertial>
      <origin rpy="0 0 0" xyz="-0.05872928812870342 0.14692321997662616 0.0013688335279802288"/>
      <mass value="0.29377075965242594"/>
      <inertia ixx="0.000983" ixy="-0.0" ixz="-0.0" iyy="2.2e-05" iyz="1.3e-05" izz="0.00098"/>
    </inertial>
    <visual>
      <origin rpy="0 0 0" xyz="-0.058737 -0.000949 -0.099647"/>
      <geometry>
        <mesh filename="package://photonfocus_camera_description/meshes/Component5_1_1_1_1.stl" scale="0.001 0.001 0.001"/>
      </geometry>
      <material name="silver"/>
    </visual>
    <collision>
      <origin rpy="0 0 0" xyz="-0.058737 -0.000949 -0.099647"/>
      <geometry>
        <mesh filename="package://photonfocus_camera_description/meshes/Component5_1_1_1_1.stl" scale="0.001 0.001 0.001"/>
      </geometry>
    </collision>
  </link>
  <joint name="base_joint" type="fixed">
    <origin rpy="0 0 0" xyz="0 0 0"/>
    <parent link="lbr_link_ee"/>
    <child link="base_link"/>
  </joint>
  <joint name="Rigid28" type="fixed">
    <origin rpy="0 0 0" xyz="-0.005763 0.000949 0.009647"/>
    <parent link="base_link"/>
    <child link="Component8_1_1_1_1"/>
  </joint>
  <joint name="Rigid29" type="fixed">
    <origin rpy="0 0 0" xyz="0.0 0.0 0.05"/>
    <parent link="Component8_1_1_1_1"/>
    <child link="Component7_1_1_1_1"/>
  </joint>
  <joint name="Rigid30" type="fixed">
    <origin rpy="0 0 0" xyz="0.0 0.0 0.015"/>
    <parent link="Component7_1_1_1_1"/>
    <child link="Component6_1_1_1_1"/>
  </joint>
  <joint name="Rigid31" type="fixed">
    <origin rpy="0 0 0" xyz="0.0085 0.0 0.01"/>
    <parent link="Component6_1_1_1_1"/>
    <child link="Component2_1_1_1_1"/>
  </joint>
  <joint name="Rigid32" type="fixed">
    <origin rpy="0 0 0" xyz="0.000385 0.015032 0.0153"/>
    <parent link="Component2_1_1_1_1"/>
    <child link="Component3_1_1_1_1"/>
  </joint>
  <joint name="Rigid33" type="fixed">
    <origin rpy="0 0 0" xyz="0.0005 0.12 0.015"/>
    <parent link="Component2_1_1_1_1"/>
    <child link="Component4_1_1_1_1"/>
  </joint>
  <joint name="Rigid34" type="fixed">
    <origin rpy="0 0 0" xyz="0.0555 -0.12 0.0"/>
    <parent link="Component4_1_1_1_1"/>
    <child link="Component5_1_1_1_1"/>
  </joint>
</robot>
